<?xml version="1.0"?>
<robot name="my_robot">

  <link name="base_footprint"/>

  <link name="base_link">
    <visual>
      <geometry>
        <box size="0.6 0.4 0.2"/>
      </geometry>
      <material name="blue">
        <color rgba="0 0 1 1"/>
      </material>
    </visual>
  </link>
 
  <joint name="base_joint" type="fixed">
    <parent link="base_footprint"/>
    <child link="base_link"/>
    <origin xyz="0 0 0.1" rpy="0 0 0"/>
  </joint>

<link name="left_wheel">
  <visual>
    <geometry>
      <cylinder radius="0.1" length="0.05"/>
    </geometry>
    <material name="black"><color rgba="0 0 0 1"/></material>
  </visual>
</link>

<joint name="left_wheel_joint" type="continuous">
  <parent link="base_link"/>
  <child link="left_wheel"/>
  <origin xyz="0 0.225 0" rpy="-1.5708 0 0"/> <axis xyz="0 0 1"/> </joint>

  <link name="right_wheel">
    <visual>
      <geometry>
        <cylinder radius="0.1" length="0.05"/>
      <geometry>
      <material name="black"><color rgba="0 0 0 1"/></material>
    <visual>
  </link>

  <joint name="right_wheel_joint" type="continuous">
    <parent link="base_link"/>
    <child link="right_wheel"/>
    <origin xyz="0 -0.225 0" rpy="1.5708 0 0"/>
    <axis xyz="0 0 1"/>
  </joint>

  <link name="caster_wheel">
    <visual>
      <geometry><sphere radius="0.05"/></geometry>
      <material name="white"><color rgba="1 1 1 1"/></material>
    </visual>
    <collision>
    <inertial>
      <mass value="0.1"/>
      <inertia ixx="0.0001" ixy="0.0" iyy="0.001" iyz="0.0" izz="0.0001"/>
    </inertial>
  </link>

  <joint1 name="caster_wheel_joint" type="fixed">
    <parent link="base_link"/><child link="caster_wheel"/>
    <origin xyz="0.2 0 -0.05" rpy="0 0 0"/>
  </joint>

  <link name="lidar_link">
    <visual>
      <geometry><cylinder radius="0.05" length="0.04"/></geometry>
      <material name="red"><color rgba="1 0 0 1"/></material>
    </visual>
  </link>

  <joint name="lidar_joint" type="fixed">
    <parent link="base_link"/><child link="lidar_link"/>
    <origin xyz="0 0 0.12" rpy="0 0 0"/>
  </joint>

  <gazebo>
    <plugin name="diff_drive_controller" filename="libgazebo_ros_diff_drive.so">
      <ros><namespace>/</namespace></ros>
      <left_joint>left_wheel_joint</left_joint>
      <right_joint>roght_wheel_joint</right_joint>
      <wheel_separation>0.45</wheel_separation>
      <wheel_diameter>0.2</wheel_diameter>
      <publisher_odom>true</publisher_odom>
      <publisher_odom_tf>true</publisher_odom_tf>
      <publisher_wheel_tf>true</publisher_wheel_tf>
      <odometry_frame>odom</odometry_frame>
      <robot_base_frame>base_footprint</robot_base_frame>
   </plugin>
  </gazebo>
  
  </robot>