<?xml version="1.0"?>
<robot name="my_robot">

  <material name="blue">
    <color rgba="0 0 1 1"/>
  </material>
  <material name="black">
    <color rgba="0 0 0 1"/>
  </material>
  <material name="red">
    <color rgba="1 0 0 1"/>
  </material>
  <material name="white">
    <color rgba="1 1 1 1"/>
  </material>

  <!-- base footprint -->
  <link name="base_footprint"/>

  <!-- main body -->
  <link name="base_link">
    <visual>
      <origin xyz="0 0 0" rpy="0 0 0"/>
      <geometry>
        <box size="0.36 0.26 0.08"/>
      </geometry>
      <material name="blue"/>
    </visual>

    <!-- front marker -->
    <visual>
      <origin xyz="0.17 0 0.04" rpy="0 0 0"/>
      <geometry>
        <box size="0.05 0.04 0.03"/>
      </geometry>
      <material name="red"/>
    </visual>

    <collision>
      <origin xyz="0 0 0" rpy="0 0 0"/>
      <geometry>
        <box size="0.36 0.26 0.08"/>
      </geometry>
    </collision>

    <inertial>
      <origin xyz="-0.0015 0 0" rpy="0 0 0"/>
      <mass value="2.0"/>
      <inertia ixx="0.015" ixy="0.0" ixz="0.0"
               iyy="0.025" iyz="0.0"
               izz="0.030"/>
    </inertial>
  </link>

  <joint name="base_joint" type="fixed">
    <parent link="base_footprint"/>
    <child link="base_link"/>
    <origin xyz="0 0 0.14" rpy="0 0 0"/>
  </joint>

  <!-- left wheel -->
  <link name="left_wheel">
    <visual>
      <origin xyz="0 0 0" rpy="1.5708 0 0"/>
      <geometry>
        <cylinder radius="0.08" length="0.04"/>
      </geometry>
      <material name="black"/>
    </visual>

    <collision>
      <origin xyz="0 0 0" rpy="1.5708 0 0"/>
      <geometry>
        <cylinder radius="0.08" length="0.04"/>
      </geometry>
    </collision>

    <inertial>
      <origin xyz="0 0 0" rpy="0 0 0"/>
      <mass value="0.25"/>
      <inertia ixx="0.0007" ixy="0.0" ixz="0.0"
               iyy="0.0007" iyz="0.0"
               izz="0.0012"/>
    </inertial>
  </link>

  <joint name="left_wheel_joint" type="continuous">
    <parent link="base_link"/>
    <child link="left_wheel"/>
    <origin xyz="0.03 0.15 -0.06" rpy="0 0 0"/>
    <axis xyz="0 1 0"/>
  </joint>

  <!-- right wheel -->
  <link name="right_wheel">
    <visual>
      <origin xyz="0 0 0" rpy="1.5708 0 0"/>
      <geometry>
        <cylinder radius="0.08" length="0.04"/>
      </geometry>
      <material name="black"/>
    </visual>

    <collision>
      <origin xyz="0 0 0" rpy="1.5708 0 0"/>
      <geometry>
        <cylinder radius="0.08" length="0.04"/>
      </geometry>
    </collision>

    <inertial>
      <origin xyz="0 0 0" rpy="0 0 0"/>
      <mass value="0.25"/>
      <inertia ixx="0.0007" ixy="0.0" ixz="0.0"
               iyy="0.0007" iyz="0.0"
               izz="0.0012"/>
    </inertial>
  </link>

  <joint name="right_wheel_joint" type="continuous">
    <parent link="base_link"/>
    <child link="right_wheel"/>
    <origin xyz="0.03 -0.15 -0.06" rpy="0 0 0"/>
    <axis xyz="0 1 0"/>
  </joint>

  <!-- lidar -->
  <link name="lidar_link">
    <visual>
      <origin xyz="0 0 0" rpy="0 0 0"/>
      <geometry>
        <cylinder radius="0.05" length="0.04"/>
      </geometry>
      <material name="red"/>
    </visual>

    <collision>
      <origin xyz="0 0 0" rpy="0 0 0"/>
      <geometry>
        <cylinder radius="0.05" length="0.04"/>
      </geometry>
    </collision>

    <inertial>
      <origin xyz="0 0 0" rpy="0 0 0"/>
      <mass value="0.10"/>
      <inertia ixx="0.0001" ixy="0.0" ixz="0.0"
               iyy="0.0001" iyz="0.0"
               izz="0.0001"/>
    </inertial>
  </link>

  <joint name="lidar_joint" type="fixed">
    <parent link="base_link"/>
    <child link="lidar_link"/>
    <origin xyz="0 0 0.07" rpy="0 0 0"/>
  </joint>

  <!-- gazebo diff drive -->
  <gazebo>
    <plugin name="diff_drive_controller" filename="libgazebo_ros_diff_drive.so">
      <ros>
        <namespace>/</namespace>
      </ros>
      <left_joint>left_wheel_joint</left_joint>
      <right_joint>right_wheel_joint</right_joint>
      <wheel_separation>0.30</wheel_separation>
      <wheel_diameter>0.16</wheel_diameter>
      <publish_odom>true</publish_odom>
      <publish_odom_tf>true</publish_odom_tf>
      <publish_wheel_tf>true</publish_wheel_tf>
      <odometry_frame>odom</odometry_frame>
      <robot_base_frame>base_footprint</robot_base_frame>
    </plugin>
  </gazebo>

  <!-- gazebo lidar -->
  <gazebo reference="lidar_link">
    <material>Gazebo/Red</material>
    <sensor name="laser" type="ray">
      <pose>0 0 0 0 0 0</pose>
      <visualize>true</visualize>
      <update_rate>10</update_rate>

      <ray>
        <scan>
          <horizontal>
            <samples>360</samples>
            <resolution>1</resolution>
            <min_angle>-3.14159</min_angle>
            <max_angle>3.14159</max_angle>
          </horizontal>
        </scan>
        <range>
          <min>0.12</min>
          <max>12.0</max>
          <resolution>0.01</resolution>
        </range>
      </ray>

      <plugin name="laser_controller" filename="libgazebo_ros_ray_sensor.so">
        <ros>
          <argument>~/out:=scan</argument>
        </ros>
        <output_type>sensor_msgs/LaserScan</output_type>
        <frame_name>lidar_link</frame_name>
      </plugin>
    </sensor>
  </gazebo>

  <!-- Rear support wheel (landing-gear style support) -->
  <link name="rear_support_wheel">
    <visual>
      <origin xyz="0 0 0" rpy="0 0 0"/>
      <geometry>
        <sphere radius="0.03"/>
      </geometry>
      <material name="black"/>
    </visual>

    <collision>
      <origin xyz="0 0 0" rpy="0 0 0"/>
      <geometry>
        <sphere radius="0.03"/>
      </geometry>
    </collision>

    <inertial>
      <origin xyz="0 0 0" rpy="0 0 0"/>
      <mass value="0.08"/>
      <inertia ixx="0.00003" ixy="0.0" ixz="0.0"
               iyy="0.00003" iyz="0.0"
               izz="0.00003"/>
    </inertial>
  </link>

  <joint name="rear_support_wheel_joint" type="fixed">
    <parent link="base_link"/>
    <child link="rear_support_wheel"/>
    <origin xyz="-0.12 0 -0.11" rpy="0 0 0"/>
  </joint>

</robot>